<sdf version='1.7'>
  <world name='default'>
    <light name='sun' type='directional'>
      <cast_shadows>1</cast_shadows>
      <pose>0 0 10 0 -0 0</pose>
      <diffuse>0.8 0.8 0.8 1</diffuse>
      <specular>0.2 0.2 0.2 1</specular>
      <attenuation>
        <range>1000</range>
        <constant>0.9</constant>
        <linear>0.01</linear>
        <quadratic>0.001</quadratic>
      </attenuation>
      <direction>-0.5 0.1 -0.9</direction>
      <spot>
        <inner_angle>0</inner_angle>
        <outer_angle>0</outer_angle>
        <falloff>0</falloff>
      </spot>
    </light>
    <model name='ground_plane'>
      <static>1</static>
      <link name='link'>
        <collision name='collision'>
          <geometry>
            <plane>
              <normal>0 0 1</normal>
              <size>100 100</size>
            </plane>
          </geometry>
          <surface>
            <friction>
              <ode>
                <mu>100</mu>
                <mu2>50</mu2>
              </ode>
              <torsional>
                <ode/>
              </torsional>
            </friction>
            <contact>
              <ode/>
            </contact>
            <bounce/>
          </surface>
          <max_contacts>10</max_contacts>
        </collision>
        <visual name='visual'>
          <cast_shadows>0</cast_shadows>
          <geometry>
            <plane>
              <normal>0 0 1</normal>
              <size>100 100</size>
            </plane>
          </geometry>
          <material>
            <script>
              <uri>file://media/materials/scripts/gazebo.material</uri>
              <name>Gazebo/Grey</name>
            </script>
          </material>
        </visual>
        <self_collide>0</self_collide>
        <enable_wind>0</enable_wind>
        <kinematic>0</kinematic>
      </link>
    </model>
    <gravity>0 0 -9.8</gravity>
    <magnetic_field>6e-06 2.3e-05 -4.2e-05</magnetic_field>
    <atmosphere type='adiabatic'/>
    <physics type='ode'>
      <max_step_size>0.001</max_step_size>
      <real_time_factor>1</real_time_factor>
      <real_time_update_rate>1000</real_time_update_rate>
    </physics>
    <scene>
      <ambient>0.4 0.4 0.4 1</ambient>
      <background>0.7 0.7 0.7 1</background>
      <shadows>1</shadows>
    </scene>
    <wind/>
    <spherical_coordinates>
      <surface_model>EARTH_WGS84</surface_model>
      <latitude_deg>0</latitude_deg>
      <longitude_deg>0</longitude_deg>
      <elevation>0</elevation>
      <heading_deg>0</heading_deg>
    </spherical_coordinates>
    <model name='fire_hydrant'>
      <static>1</static>
      <link name='link'>
        <collision name='collision'>
          <geometry>
            <mesh>
              <uri>model://fire_hydrant/meshes/fire_hydrant.dae</uri>
            </mesh>
          </geometry>
          <max_contacts>10</max_contacts>
          <surface>
            <contact>
              <ode/>
            </contact>
            <bounce/>
            <friction>
              <torsional>
                <ode/>
              </torsional>
              <ode/>
            </friction>
          </surface>
        </collision>
        <visual name='visual'>
          <geometry>
            <mesh>
              <uri>model://fire_hydrant/meshes/fire_hydrant.dae</uri>
            </mesh>
          </geometry>
        </visual>
        <self_collide>0</self_collide>
        <enable_wind>0</enable_wind>
        <kinematic>0</kinematic>
      </link>
      <pose>2.00272 -0.058217 0 0 -0 0</pose>
    </model>
    <model name='hatchback_red'>
      <static>1</static>
      <link name='link'>
        <collision name='collision'>
          <pose>0 0 0 0 -0 1.5708</pose>
          <geometry>
            <mesh>
              <scale>0.0254 0.0254 0.0254</scale>
              <uri>model://hatchback_red/meshes/hatchback.obj</uri>
            </mesh>
          </geometry>
          <max_contacts>10</max_contacts>
          <surface>
            <contact>
              <ode/>
            </contact>
            <bounce/>
            <friction>
              <torsional>
                <ode/>
              </torsional>
              <ode/>
            </friction>
          </surface>
        </collision>
        <visual name='visual'>
          <pose>0 0 0 0 -0 1.5708</pose>
          <geometry>
            <mesh>
              <scale>0.0254 0.0254 0.0254</scale>
              <uri>model://hatchback_red/meshes/hatchback.obj</uri>
            </mesh>
          </geometry>
        </visual>
        <self_collide>0</self_collide>
        <enable_wind>0</enable_wind>
        <kinematic>0</kinematic>
      </link>
      <pose>3.30028 1.77997 0 0 -0 0</pose>
    </model>
    <state world_name='default'>
      <sim_time>167 494000000</sim_time>
      <real_time>51 176366484</real_time>
      <wall_time>1656156748 763653553</wall_time>
      <iterations>51022</iterations>
      <model name='fire_hydrant'>
        <pose>2.76753 -0.534333 0 0 -0 0</pose>
        <scale>1 1 1</scale>
        <link name='link'>
          <pose>2.76753 -0.534333 0 0 -0 0</pose>
          <velocity>0 0 0 0 -0 0</velocity>
          <acceleration>0 0 0 0 -0 0</acceleration>
          <wrench>0 0 0 0 -0 0</wrench>
        </link>
      </model>
      <model name='ground_plane'>
        <pose>0 0 0 0 -0 0</pose>
        <scale>1 1 1</scale>
        <link name='link'>
          <pose>0 0 0 0 -0 0</pose>
          <velocity>0 0 0 0 -0 0</velocity>
          <acceleration>0 0 0 0 -0 0</acceleration>
          <wrench>0 0 0 0 -0 0</wrench>
        </link>
      </model>
      <model name='hatchback_red'>
        <pose>4.68183 2.39572 0 0 0 -1.55496</pose>
        <scale>1 1 1</scale>
        <link name='link'>
          <pose>4.68183 2.39572 0 0 0 -1.55496</pose>
          <velocity>0 0 0 0 -0 0</velocity>
          <acceleration>0 0 0 0 -0 0</acceleration>
          <wrench>0 0 0 0 -0 0</wrench>
        </link>
      </model>
      <model name='turtlebot3_waffle'>
        <pose>0.00155 2e-06 0.00783 3.2e-05 0.006693 0.002796</pose>
        <scale>1 1 1</scale>
        <link name='base_footprint'>
          <pose>0.00155 2e-06 0.00783 3.2e-05 0.006693 0.002796</pose>
          <velocity>-2e-06 -5.8e-05 -0.090527 2.9e-05 0.002656 4.9e-05</velocity>
          <acceleration>0.003487 0.000278 -1.02527 0.010574 -0.256394 5.3e-05</acceleration>
          <wrench>0.003487 0.000278 -1.02527 0 -0 0</wrench>
        </link>
        <link name='base_link'>
          <pose>0.00155 2e-06 0.00783 3.2e-05 0.006694 0.002796</pose>
          <velocity>4.1e-05 -5.9e-05 -0.090469 2.6e-05 0.002442 4.9e-05</velocity>
          <acceleration>-0.008869 -0.000221 -1.04151 0.010691 -0.256743 1.6e-05</acceleration>
          <wrench>-0.012176 -0.000303 -1.42991 0 -0 0</wrench>
        </link>
        <link name='base_scan'>
          <pose>0.00155 2e-06 0.007831 3.2e-05 0.006688 0.002796</pose>
          <velocity>-1.4e-05 -5.9e-05 -0.090552 3.1e-05 0.003659 4.9e-05</velocity>
          <acceleration>-0.025086 -0.000868 -1.03825 0.010404 -0.258485 6e-05</acceleration>
          <wrench>-0.00286 -9.9e-05 -0.11836 0 -0 0</wrench>
        </link>
        <link name='camera_link'>
          <pose>0.00155 2e-06 0.00783 3.2e-05 0.006689 0.002796</pose>
          <velocity>-8e-06 -5.9e-05 -0.090534 3e-05 0.003377 4.9e-05</velocity>
          <acceleration>0.003664 0.000291 -1.02503 0.010469 -0.258083 6e-05</acceleration>
          <wrench>0.003664 0.000291 -1.02503 0 -0 0</wrench>
        </link>
        <link name='camera_rgb_frame'>
          <pose>0.071395 -0.046806 0.114365 3.2e-05 0.006689 0.002796</pose>
          <velocity>0.000375 -5.4e-05 -0.090801 2e-05 0.003385 4.1e-05</velocity>
          <acceleration>-0.051287 -0.001924 -0.989903 0.010487 -0.258124 4.6e-05</acceleration>
          <wrench>-0.001795 -6.7e-05 -0.034647 0 -0 0</wrench>
        </link>
        <link name='caster_back_left_link'>
          <pose>-0.175651 0.063507 0.005016 -1.0694 -0.114735 -0.009977</pose>
          <velocity>-1e-05 -6.3e-05 -0.089706 0.009957 -0.003644 0</velocity>
          <acceleration>0.00248 -0.000755 -1.12688 0 -0 0</acceleration>
          <wrench>2e-06 -1e-06 -0.001127 0 -0 0</wrench>
        </link>
        <link name='caster_back_right_link'>
          <pose>-0.175293 -0.064492 0.005012 -1.16182 -0.10881 -0.0074</pose>
          <velocity>-1e-06 -6.3e-05 -0.08972 0.008075 -0.003712 0</velocity>
          <acceleration>0.001804 -0.000786 -1.12608 0 -0 0</acceleration>
          <wrench>2e-06 -1e-06 -0.001126 0 -0 0</wrench>
        </link>
        <link name='imu_link'>
          <pose>0.00155 2e-06 0.00783 3.2e-05 0.006689 0.002796</pose>
          <velocity>-7e-06 -5.9e-05 -0.090534 3.5e-05 0.003421 4.9e-05</velocity>
          <acceleration>0.003562 0.000283 -1.02516 0.010256 -0.255805 6.6e-05</acceleration>
          <wrench>0.003562 0.000283 -1.02516 0 -0 0</wrench>
        </link>
        <link name='wheel_left_link'>
          <pose>0.000799 -0 0.007849 2.6e-05 0.039521 0.002823</pose>
          <velocity>2.2e-05 -1.6e-05 -0.090753 0.001632 0.002279 -5e-06</velocity>
          <acceleration>-0.003212 6e-06 -1.02384 -0.000408 -0.097129 0.006064</acceleration>
          <wrench>-0.000321 1e-06 -0.102384 0 -0 0</wrench>
        </link>
        <link name='wheel_right_link'>
          <pose>0.000229 -2e-06 0.007876 2.7e-05 0.063903 0.002843</pose>
          <velocity>2.8e-05 -1.6e-05 -0.090292 0.001634 0.002705 -7e-06</velocity>
          <acceleration>-0.003174 2e-06 -1.02658 -0.000285 -0.095987 0.006069</acceleration>
          <wrench>-0.000317 0 -0.102657 0 -0 0</wrench>
        </link>
      </model>
      <light name='sun'>
        <pose>0 0 10 0 -0 0</pose>
      </light>
    </state>
    <gui fullscreen='0'>
      <camera name='user_camera'>
        <pose>-2.05423 -16.349 9.27242 -0 0.427642 0.924186</pose>
        <view_controller>orbit</view_controller>
        <projection_type>perspective</projection_type>
      </camera>
    </gui>
    <model name='turtlebot3_waffle'>
      <pose>-0 -0 0 0 -0 0</pose>
      <link name='base_footprint'>
        <self_collide>0</self_collide>
        <inertial>
          <pose>0 0 0 0 -0 0</pose>
          <inertia>
            <ixx>1</ixx>
            <ixy>0</ixy>
            <ixz>0</ixz>
            <iyy>1</iyy>
            <iyz>0</iyz>
            <izz>1</izz>
          </inertia>
          <mass>1</mass>
        </inertial>
        <enable_wind>0</enable_wind>
        <kinematic>0</kinematic>
      </link>
      <link name='base_link'>
        <inertial>
          <pose>-0.064 0 0.048 0 -0 0</pose>
          <inertia>
            <ixx>0.0421114</ixx>
            <ixy>0</ixy>
            <ixz>0</ixz>
            <iyy>0.0421114</iyy>
            <iyz>0</iyz>
            <izz>0.0752549</izz>
          </inertia>
          <mass>1.37291</mass>
        </inertial>
        <collision name='base_collision'>
          <pose>-0.064 0 0.048 0 -0 0</pose>
          <geometry>
            <box>
              <size>0.265 0.265 0.089</size>
            </box>
          </geometry>
          <max_contacts>10</max_contacts>
          <surface>
            <contact>
              <ode/>
            </contact>
            <bounce/>
            <friction>
              <torsional>
                <ode/>
              </torsional>
              <ode/>
            </friction>
          </surface>
        </collision>
        <visual name='base_visual'>
          <pose>-0.064 0 0 0 -0 0</pose>
          <geometry>
            <mesh>
              <uri>model://turtlebot3_waffle/meshes/waffle_base.dae</uri>
              <scale>0.001 0.001 0.001</scale>
            </mesh>
          </geometry>
        </visual>
        <self_collide>0</self_collide>
        <enable_wind>0</enable_wind>
        <kinematic>0</kinematic>
      </link>
      <link name='imu_link'>
        <sensor name='tb3_imu' type='imu'>
          <always_on>1</always_on>
          <update_rate>200</update_rate>
          <imu>
            <angular_velocity>
              <x>
                <noise type='gaussian'>
                  <mean>0</mean>
                  <stddev>0.0002</stddev>
                </noise>
              </x>
              <y>
                <noise type='gaussian'>
                  <mean>0</mean>
                  <stddev>0.0002</stddev>
                </noise>
              </y>
              <z>
                <noise type='gaussian'>
                  <mean>0</mean>
                  <stddev>0.0002</stddev>
                </noise>
              </z>
            </angular_velocity>
            <linear_acceleration>
              <x>
                <noise type='gaussian'>
                  <mean>0</mean>
                  <stddev>0.017</stddev>
                </noise>
              </x>
              <y>
                <noise type='gaussian'>
                  <mean>0</mean>
                  <stddev>0.017</stddev>
                </noise>
              </y>
              <z>
                <noise type='gaussian'>
                  <mean>0</mean>
                  <stddev>0.017</stddev>
                </noise>
              </z>
            </linear_acceleration>
            <angular_velocity/>
            <linear_acceleration/>
          </imu>
          <plugin name='turtlebot3_imu' filename='libgazebo_ros_imu_sensor.so'>
            <ros>
              <remapping>~/out:=imu</remapping>
            </ros>
          </plugin>
        </sensor>
        <self_collide>0</self_collide>
        <inertial>
          <pose>0 0 0 0 -0 0</pose>
          <inertia>
            <ixx>1</ixx>
            <ixy>0</ixy>
            <ixz>0</ixz>
            <iyy>1</iyy>
            <iyz>0</iyz>
            <izz>1</izz>
          </inertia>
          <mass>1</mass>
        </inertial>
        <enable_wind>0</enable_wind>
        <kinematic>0</kinematic>
      </link>
      <link name='base_scan'>
        <inertial>
          <pose>-0.052 0 0.111 0 -0 0</pose>
          <inertia>
            <ixx>0.001</ixx>
            <ixy>0</ixy>
            <ixz>0</ixz>
            <iyy>0.001</iyy>
            <iyz>0</iyz>
            <izz>0.001</izz>
          </inertia>
          <mass>0.114</mass>
        </inertial>
        <collision name='lidar_sensor_collision'>
          <pose>-0.052 0 0.111 0 -0 0</pose>
          <geometry>
            <cylinder>
              <radius>0.0508</radius>
              <length>0.055</length>
            </cylinder>
          </geometry>
          <max_contacts>10</max_contacts>
          <surface>
            <contact>
              <ode/>
            </contact>
            <bounce/>
            <friction>
              <torsional>
                <ode/>
              </torsional>
              <ode/>
            </friction>
          </surface>
        </collision>
        <visual name='lidar_sensor_visual'>
          <pose>-0.064 0 0.121 0 -0 0</pose>
          <geometry>
            <mesh>
              <uri>model://turtlebot3_waffle/meshes/lds.dae</uri>
              <scale>0.001 0.001 0.001</scale>
            </mesh>
          </geometry>
        </visual>
        <sensor name='hls_lfcd_lds' type='ray'>
          <always_on>1</always_on>
          <visualize>1</visualize>
          <pose>-0.064 0 0.121 0 -0 0</pose>
          <update_rate>5</update_rate>
          <ray>
            <scan>
              <horizontal>
                <samples>360</samples>
                <resolution>1</resolution>
                <min_angle>0</min_angle>
                <max_angle>6.28</max_angle>
              </horizontal>
              <vertical>
                <samples>1</samples>
                <min_angle>0</min_angle>
                <max_angle>0</max_angle>
              </vertical>
            </scan>
            <range>
              <min>0.12</min>
              <max>3.5</max>
              <resolution>0.015</resolution>
            </range>
            <noise>
              <type>gaussian</type>
              <mean>0</mean>
              <stddev>0.01</stddev>
            </noise>
          </ray>
          <plugin name='turtlebot3_laserscan' filename='libgazebo_ros_ray_sensor.so'>
            <ros>
              <remapping>~/out:=scan</remapping>
            </ros>
            <output_type>sensor_msgs/LaserScan</output_type>
            <frame_name>base_scan</frame_name>
          </plugin>
        </sensor>
        <self_collide>0</self_collide>
        <enable_wind>0</enable_wind>
        <kinematic>0</kinematic>
      </link>
      <link name='wheel_left_link'>
        <inertial>
          <pose>0 0.144 0.023 -1.57 0 0</pose>
          <inertia>
            <ixx>1.11756e-05</ixx>
            <ixy>-4.23698e-11</ixy>
            <ixz>-5.93817e-09</ixz>
            <iyy>1.11924e-05</iyy>
            <iyz>-1.44001e-11</iyz>
            <izz>2.07126e-05</izz>
          </inertia>
          <mass>0.1</mass>
        </inertial>
        <collision name='wheel_left_collision'>
          <pose>0 0.144 0.023 -1.57 0 0</pose>
          <geometry>
            <cylinder>
              <radius>0.033</radius>
              <length>0.018</length>
            </cylinder>
          </geometry>
          <surface>
            <friction>
              <ode>
                <mu>100000</mu>
                <mu2>100000</mu2>
                <fdir1>0 0 0</fdir1>
                <slip1>0</slip1>
                <slip2>0</slip2>
              </ode>
              <torsional>
                <ode/>
              </torsional>
            </friction>
            <contact>
              <ode>
                <soft_cfm>0</soft_cfm>
                <soft_erp>0.2</soft_erp>
                <kp>100000</kp>
                <kd>1</kd>
                <max_vel>0.01</max_vel>
                <min_depth>0.001</min_depth>
              </ode>
            </contact>
            <bounce/>
          </surface>
          <max_contacts>10</max_contacts>
        </collision>
        <visual name='wheel_left_visual'>
          <pose>0 0.144 0.023 0 -0 0</pose>
          <geometry>
            <mesh>
              <uri>model://turtlebot3_waffle/meshes/tire.dae</uri>
              <scale>0.001 0.001 0.001</scale>
            </mesh>
          </geometry>
        </visual>
        <self_collide>0</self_collide>
        <enable_wind>0</enable_wind>
        <kinematic>0</kinematic>
      </link>
      <link name='wheel_right_link'>
        <inertial>
          <pose>0 -0.144 0.023 -1.57 0 0</pose>
          <inertia>
            <ixx>1.11756e-05</ixx>
            <ixy>-4.23698e-11</ixy>
            <ixz>-5.93817e-09</ixz>
            <iyy>1.11924e-05</iyy>
            <iyz>-1.44001e-11</iyz>
            <izz>2.07126e-05</izz>
          </inertia>
          <mass>0.1</mass>
        </inertial>
        <collision name='wheel_right_collision'>
          <pose>0 -0.144 0.023 -1.57 0 0</pose>
          <geometry>
            <cylinder>
              <radius>0.033</radius>
              <length>0.018</length>
            </cylinder>
          </geometry>
          <surface>
            <friction>
              <ode>
                <mu>100000</mu>
                <mu2>100000</mu2>
                <fdir1>0 0 0</fdir1>
                <slip1>0</slip1>
                <slip2>0</slip2>
              </ode>
              <torsional>
                <ode/>
              </torsional>
            </friction>
            <contact>
              <ode>
                <soft_cfm>0</soft_cfm>
                <soft_erp>0.2</soft_erp>
                <kp>100000</kp>
                <kd>1</kd>
                <max_vel>0.01</max_vel>
                <min_depth>0.001</min_depth>
              </ode>
            </contact>
            <bounce/>
          </surface>
          <max_contacts>10</max_contacts>
        </collision>
        <visual name='wheel_right_visual'>
          <pose>0 -0.144 0.023 0 -0 0</pose>
          <geometry>
            <mesh>
              <uri>model://turtlebot3_waffle/meshes/tire.dae</uri>
              <scale>0.001 0.001 0.001</scale>
            </mesh>
          </geometry>
        </visual>
        <self_collide>0</self_collide>
        <enable_wind>0</enable_wind>
        <kinematic>0</kinematic>
      </link>
      <link name='caster_back_right_link'>
        <pose>-0.177 -0.064 -0.004 -1.57 0 0</pose>
        <inertial>
          <mass>0.001</mass>
          <inertia>
            <ixx>1e-05</ixx>
            <ixy>0</ixy>
            <ixz>0</ixz>
            <iyy>1e-05</iyy>
            <iyz>0</iyz>
            <izz>1e-05</izz>
          </inertia>
          <pose>0 0 0 0 -0 0</pose>
        </inertial>
        <collision name='collision'>
          <geometry>
            <sphere>
              <radius>0.005</radius>
            </sphere>
          </geometry>
          <surface>
            <contact>
              <ode>
                <soft_cfm>0</soft_cfm>
                <soft_erp>0.2</soft_erp>
                <kp>100000</kp>
                <kd>1</kd>
                <max_vel>0.01</max_vel>
                <min_depth>0.001</min_depth>
              </ode>
            </contact>
            <bounce/>
            <friction>
              <torsional>
                <ode/>
              </torsional>
              <ode/>
            </friction>
          </surface>
          <max_contacts>10</max_contacts>
        </collision>
        <self_collide>0</self_collide>
        <enable_wind>0</enable_wind>
        <kinematic>0</kinematic>
      </link>
      <link name='caster_back_left_link'>
        <pose>-0.177 0.064 -0.004 -1.57 0 0</pose>
        <inertial>
          <mass>0.001</mass>
          <inertia>
            <ixx>1e-05</ixx>
            <ixy>0</ixy>
            <ixz>0</ixz>
            <iyy>1e-05</iyy>
            <iyz>0</iyz>
            <izz>1e-05</izz>
          </inertia>
          <pose>0 0 0 0 -0 0</pose>
        </inertial>
        <collision name='collision'>
          <geometry>
            <sphere>
              <radius>0.005</radius>
            </sphere>
          </geometry>
          <surface>
            <contact>
              <ode>
                <soft_cfm>0</soft_cfm>
                <soft_erp>0.2</soft_erp>
                <kp>100000</kp>
                <kd>1</kd>
                <max_vel>0.01</max_vel>
                <min_depth>0.001</min_depth>
              </ode>
            </contact>
            <bounce/>
            <friction>
              <torsional>
                <ode/>
              </torsional>
              <ode/>
            </friction>
          </surface>
          <max_contacts>10</max_contacts>
        </collision>
        <self_collide>0</self_collide>
        <enable_wind>0</enable_wind>
        <kinematic>0</kinematic>
      </link>
      <link name='camera_link'>
        <self_collide>0</self_collide>
        <inertial>
          <pose>0 0 0 0 -0 0</pose>
          <inertia>
            <ixx>1</ixx>
            <ixy>0</ixy>
            <ixz>0</ixz>
            <iyy>1</iyy>
            <iyz>0</iyz>
            <izz>1</izz>
          </inertia>
          <mass>1</mass>
        </inertial>
        <enable_wind>0</enable_wind>
        <kinematic>0</kinematic>
      </link>
      <link name='camera_rgb_frame'>
        <inertial>
          <pose>0.069 -0.047 0.107 0 -0 0</pose>
          <inertia>
            <ixx>0.001</ixx>
            <ixy>0</ixy>
            <ixz>0</ixz>
            <iyy>0.001</iyy>
            <iyz>0</iyz>
            <izz>0.001</izz>
          </inertia>
          <mass>0.035</mass>
        </inertial>
        <pose>0.069 -0.047 0.107 0 -0 0</pose>
        <sensor name='camera' type='camera'>
          <always_on>1</always_on>
          <visualize>1</visualize>
          <update_rate>30</update_rate>
          <camera name='intel_realsense_r200'>
            <horizontal_fov>1.02974</horizontal_fov>
            <image>
              <width>1920</width>
              <height>1080</height>
              <format>R8G8B8</format>
            </image>
            <clip>
              <near>0.02</near>
              <far>300</far>
            </clip>
            <noise>
              <type>gaussian</type>
              <mean>0</mean>
              <stddev>0.007</stddev>
            </noise>
          </camera>
          <plugin name='camera_driver' filename='libgazebo_ros_camera.so'>
            <ros/>
          </plugin>
        </sensor>
        <self_collide>0</self_collide>
        <enable_wind>0</enable_wind>
        <kinematic>0</kinematic>
      </link>
      <joint name='base_joint' type='fixed'>
        <parent>base_footprint</parent>
        <child>base_link</child>
        <pose>0 0 0.01 0 -0 0</pose>
      </joint>
      <joint name='wheel_left_joint' type='revolute'>
        <parent>base_link</parent>
        <child>wheel_left_link</child>
        <pose>0 0.144 0.023 -1.57 0 0</pose>
        <axis>
          <xyz>0 0 1</xyz>
          <limit>
            <lower>-1e+16</lower>
            <upper>1e+16</upper>
          </limit>
          <dynamics>
            <spring_reference>0</spring_reference>
            <spring_stiffness>0</spring_stiffness>
          </dynamics>
        </axis>
      </joint>
      <joint name='wheel_right_joint' type='revolute'>
        <parent>base_link</parent>
        <child>wheel_right_link</child>
        <pose>0 -0.144 0.023 -1.57 0 0</pose>
        <axis>
          <xyz>0 0 1</xyz>
          <limit>
            <lower>-1e+16</lower>
            <upper>1e+16</upper>
          </limit>
          <dynamics>
            <spring_reference>0</spring_reference>
            <spring_stiffness>0</spring_stiffness>
          </dynamics>
        </axis>
      </joint>
      <joint name='caster_back_right_joint' type='ball'>
        <parent>base_link</parent>
        <child>caster_back_right_link</child>
      </joint>
      <joint name='caster_back_left_joint' type='ball'>
        <parent>base_link</parent>
        <child>caster_back_left_link</child>
      </joint>
      <joint name='imu_joint' type='fixed'>
        <parent>base_link</parent>
        <child>imu_link</child>
        <pose>-0.032 0 0.068 0 -0 0</pose>
        <axis>
          <xyz>0 0 1</xyz>
          <limit>
            <lower>-1e+16</lower>
            <upper>1e+16</upper>
          </limit>
        </axis>
      </joint>
      <joint name='lidar_joint' type='fixed'>
        <parent>base_link</parent>
        <child>base_scan</child>
        <pose>-0.064 0 0.121 0 -0 0</pose>
        <axis>
          <xyz>0 0 1</xyz>
          <limit>
            <lower>-1e+16</lower>
            <upper>1e+16</upper>
          </limit>
        </axis>
      </joint>
      <joint name='camera_joint' type='fixed'>
        <parent>base_link</parent>
        <child>camera_link</child>
        <pose>0.064 -0.065 0.094 0 -0 0</pose>
        <axis>
          <xyz>0 0 1</xyz>
          <limit>
            <lower>-1e+16</lower>
            <upper>1e+16</upper>
          </limit>
        </axis>
      </joint>
      <joint name='camera_rgb_joint' type='fixed'>
        <parent>camera_link</parent>
        <child>camera_rgb_frame</child>
        <pose>0.005 0.018 0.013 0 -0 0</pose>
        <axis>
          <xyz>0 0 1</xyz>
          <limit>
            <lower>-1e+16</lower>
            <upper>1e+16</upper>
          </limit>
        </axis>
      </joint>
      <plugin name='turtlebot3_diff_drive' filename='libgazebo_ros_diff_drive.so'>
        <ros/>
        <update_rate>30</update_rate>
        <left_joint>wheel_left_joint</left_joint>
        <right_joint>wheel_right_joint</right_joint>
        <wheel_separation>0.287</wheel_separation>
        <wheel_diameter>0.066</wheel_diameter>
        <max_wheel_torque>20</max_wheel_torque>
        <max_wheel_acceleration>1.0</max_wheel_acceleration>
        <command_topic>cmd_vel</command_topic>
        <publish_odom>1</publish_odom>
        <publish_odom_tf>1</publish_odom_tf>
        <publish_wheel_tf>0</publish_wheel_tf>
        <odometry_topic>odom</odometry_topic>
        <odometry_frame>odom</odometry_frame>
        <robot_base_frame>base_footprint</robot_base_frame>
      </plugin>
      <plugin name='turtlebot3_joint_state' filename='libgazebo_ros_joint_state_publisher.so'>
        <ros>
          <remapping>~/out:=joint_states</remapping>
        </ros>
        <update_rate>30</update_rate>
        <joint_name>wheel_left_joint</joint_name>
        <joint_name>wheel_right_joint</joint_name>
      </plugin>
    </model>
  </world>
</sdf>
